input4_2.txt
9
INSERT,1,FFLY,BUY,14.235,5
INSERT,2,FFLY,BUY,14.235,6
INSERT,3,FFLY,BUY,14.235,12
INSERT,4,FFLY,BUY,14.234,5
INSERT,5,FFLY,BUY,14.23,3
INSERT,6,FFLY,BUY,14.237,8
INSERT,7,FFLY,SELL,14.24,9
CANCEL,1
INSERT,8,FFLY,SELL,14.234,25
