output/output_4_2.txt
FFLY,14.234,8,8,6
FFLY,14.234,6,8,2
FFLY,14.234,11,8,3
===FFLY===
SELL,14.24,9
BUY,14.235,1
BUY,14.234,5
BUY,14.23,3
