output/output_5.txt
FFLY,46,3,2,4
FFLY,45.95,1,5,1
FFLY,45.95,1,6,1
FFLY,45.95,1,7,3
===FFLY===
SELL,46,5
BUY,45.95,16
