old_limit_order_book_project/expected_output/expected_output_4.txt
FFLY,14.235,6,8,2
FFLY,14.235,12,8,3
FFLY,14.234,5,8,4
===FFLY===
SELL,14.24,9
SELL,14.237,8
SELL,14.234,2
BUY,14.23,3
