old_limit_order_book_project/input/input_5.txt
10
INSERT,1,FFLY,BUY,45.95,5
INSERT,2,FFLY,BUY,45.95,6
INSERT,3,FFLY,BUY,45.95,12
INSERT,4,FFLY,SELL,46,8
UPDATE,2,46,3
INSERT,5,FFLY,SELL,45.95,1
UPDATE,1,45.95,3
INSERT,6,FFLY,SELL,45.95,1
UPDATE,1,45.95,5
INSERT,7,FFLY,SELL,45.95,1
